2023-08-10 01:19:15,534 ERROR: Exception on /About_Us [GET] [in /Users/danielweir/highlyfe3/venv/lib/python3.9/site-packages/flask/app.py:1414]
Traceback (most recent call last):
  File "/Users/danielweir/highlyfe3/venv/lib/python3.9/site-packages/flask/app.py", line 2190, in wsgi_app
    response = self.full_dispatch_request()
  File "/Users/danielweir/highlyfe3/venv/lib/python3.9/site-packages/flask/app.py", line 1486, in full_dispatch_request
    rv = self.handle_user_exception(e)
  File "/Users/danielweir/highlyfe3/venv/lib/python3.9/site-packages/flask/app.py", line 1484, in full_dispatch_request
    rv = self.dispatch_request()
  File "/Users/danielweir/highlyfe3/venv/lib/python3.9/site-packages/flask/app.py", line 1469, in dispatch_request
    return self.ensure_sync(self.view_functions[rule.endpoint])(**view_args)
  File "/Users/danielweir/highlyfe3/venv/lib/python3.9/site-packages/flask_login/utils.py", line 290, in decorated_view
    return current_app.ensure_sync(func)(*args, **kwargs)
  File "/Users/danielweir/highlyfe3/app/main/routes.py", line 127, in About_Us
    return render_template('About_Us.html',users=users, title='About Us', name_to_update=name_to_update, id=id, form=form, text_input=text_input)
  File "/Users/danielweir/highlyfe3/venv/lib/python3.9/site-packages/flask/templating.py", line 150, in render_template
    template = app.jinja_env.get_or_select_template(template_name_or_list)
  File "/Users/danielweir/highlyfe3/venv/lib/python3.9/site-packages/jinja2/environment.py", line 1081, in get_or_select_template
    return self.get_template(template_name_or_list, parent, globals)
  File "/Users/danielweir/highlyfe3/venv/lib/python3.9/site-packages/jinja2/environment.py", line 1010, in get_template
    return self._load_template(name, globals)
  File "/Users/danielweir/highlyfe3/venv/lib/python3.9/site-packages/jinja2/environment.py", line 969, in _load_template
    template = self.loader.load(self, name, self.make_globals(globals))
  File "/Users/danielweir/highlyfe3/venv/lib/python3.9/site-packages/jinja2/loaders.py", line 138, in load
    code = environment.compile(source, name, filename)
  File "/Users/danielweir/highlyfe3/venv/lib/python3.9/site-packages/jinja2/environment.py", line 768, in compile
    self.handle_exception(source=source_hint)
  File "/Users/danielweir/highlyfe3/venv/lib/python3.9/site-packages/jinja2/environment.py", line 936, in handle_exception
    raise rewrite_traceback_stack(source=source)
  File "/Users/danielweir/highlyfe3/app/templates/About_Us.html", line 82, in template
    {% endif %}
jinja2.exceptions.TemplateSyntaxError: Encountered unknown tag 'endif'. You probably made a nesting mistake. Jinja is expecting this tag, but currently looking for 'endfor' or 'else'. The innermost block that needs to be closed is 'for'.
2023-08-10 01:19:43,285 INFO: Highlyfe startup [in /Users/danielweir/highlyfe3/app/__init__.py:59]
2023-08-10 01:20:39,778 INFO: Highlyfe startup [in /Users/danielweir/highlyfe3/app/__init__.py:59]
2023-08-10 01:20:43,734 ERROR: Exception on /About_Us [GET] [in /Users/danielweir/highlyfe3/venv/lib/python3.9/site-packages/flask/app.py:1414]
Traceback (most recent call last):
  File "/Users/danielweir/highlyfe3/venv/lib/python3.9/site-packages/flask/app.py", line 2190, in wsgi_app
    response = self.full_dispatch_request()
  File "/Users/danielweir/highlyfe3/venv/lib/python3.9/site-packages/flask/app.py", line 1486, in full_dispatch_request
    rv = self.handle_user_exception(e)
  File "/Users/danielweir/highlyfe3/venv/lib/python3.9/site-packages/flask/app.py", line 1484, in full_dispatch_request
    rv = self.dispatch_request()
  File "/Users/danielweir/highlyfe3/venv/lib/python3.9/site-packages/flask/app.py", line 1469, in dispatch_request
    return self.ensure_sync(self.view_functions[rule.endpoint])(**view_args)
  File "/Users/danielweir/highlyfe3/venv/lib/python3.9/site-packages/flask_login/utils.py", line 290, in decorated_view
    return current_app.ensure_sync(func)(*args, **kwargs)
  File "/Users/danielweir/highlyfe3/app/main/routes.py", line 82, in About_Us
    name_to_update = User.query.all(id)
TypeError: all() takes 1 positional argument but 2 were given
2023-08-10 01:20:54,542 INFO: Highlyfe startup [in /Users/danielweir/highlyfe3/app/__init__.py:59]
2023-08-10 01:20:54,766 ERROR: Exception on /About_Us [GET] [in /Users/danielweir/highlyfe3/venv/lib/python3.9/site-packages/flask/app.py:1414]
Traceback (most recent call last):
  File "/Users/danielweir/highlyfe3/venv/lib/python3.9/site-packages/flask/app.py", line 2190, in wsgi_app
    response = self.full_dispatch_request()
  File "/Users/danielweir/highlyfe3/venv/lib/python3.9/site-packages/flask/app.py", line 1486, in full_dispatch_request
    rv = self.handle_user_exception(e)
  File "/Users/danielweir/highlyfe3/venv/lib/python3.9/site-packages/flask/app.py", line 1484, in full_dispatch_request
    rv = self.dispatch_request()
  File "/Users/danielweir/highlyfe3/venv/lib/python3.9/site-packages/flask/app.py", line 1469, in dispatch_request
    return self.ensure_sync(self.view_functions[rule.endpoint])(**view_args)
  File "/Users/danielweir/highlyfe3/venv/lib/python3.9/site-packages/flask_login/utils.py", line 290, in decorated_view
    return current_app.ensure_sync(func)(*args, **kwargs)
  File "/Users/danielweir/highlyfe3/app/main/routes.py", line 123, in About_Us
    text_input = name_to_update.text_input
AttributeError: 'list' object has no attribute 'text_input'
2023-08-10 01:21:39,815 INFO: Highlyfe startup [in /Users/danielweir/highlyfe3/app/__init__.py:59]
2023-08-10 01:22:29,199 INFO: Highlyfe startup [in /Users/danielweir/highlyfe3/app/__init__.py:59]
2023-08-10 01:22:51,265 INFO: Highlyfe startup [in /Users/danielweir/highlyfe3/app/__init__.py:59]
2023-08-10 01:24:38,782 INFO: Highlyfe startup [in /Users/danielweir/highlyfe3/app/__init__.py:59]
2023-08-10 01:24:42,295 ERROR: Exception on /About_Us [POST] [in /Users/danielweir/highlyfe3/venv/lib/python3.9/site-packages/flask/app.py:1414]
Traceback (most recent call last):
  File "/Users/danielweir/highlyfe3/venv/lib/python3.9/site-packages/flask/app.py", line 2190, in wsgi_app
    response = self.full_dispatch_request()
  File "/Users/danielweir/highlyfe3/venv/lib/python3.9/site-packages/flask/app.py", line 1486, in full_dispatch_request
    rv = self.handle_user_exception(e)
  File "/Users/danielweir/highlyfe3/venv/lib/python3.9/site-packages/flask/app.py", line 1484, in full_dispatch_request
    rv = self.dispatch_request()
  File "/Users/danielweir/highlyfe3/venv/lib/python3.9/site-packages/flask/app.py", line 1469, in dispatch_request
    return self.ensure_sync(self.view_functions[rule.endpoint])(**view_args)
  File "/Users/danielweir/highlyfe3/venv/lib/python3.9/site-packages/flask_login/utils.py", line 290, in decorated_view
    return current_app.ensure_sync(func)(*args, **kwargs)
  File "/Users/danielweir/highlyfe3/app/main/routes.py", line 87, in About_Us
    no.text_input = text_input  #
AttributeError: 'list' object has no attribute 'text_input'
2023-08-10 01:25:54,605 INFO: Highlyfe startup [in /Users/danielweir/highlyfe3/app/__init__.py:59]
2023-08-10 01:25:57,387 ERROR: Exception on /About_Us [POST] [in /Users/danielweir/highlyfe3/venv/lib/python3.9/site-packages/flask/app.py:1414]
Traceback (most recent call last):
  File "/Users/danielweir/highlyfe3/venv/lib/python3.9/site-packages/flask/app.py", line 2190, in wsgi_app
    response = self.full_dispatch_request()
  File "/Users/danielweir/highlyfe3/venv/lib/python3.9/site-packages/flask/app.py", line 1486, in full_dispatch_request
    rv = self.handle_user_exception(e)
  File "/Users/danielweir/highlyfe3/venv/lib/python3.9/site-packages/flask/app.py", line 1484, in full_dispatch_request
    rv = self.dispatch_request()
  File "/Users/danielweir/highlyfe3/venv/lib/python3.9/site-packages/flask/app.py", line 1469, in dispatch_request
    return self.ensure_sync(self.view_functions[rule.endpoint])(**view_args)
  File "/Users/danielweir/highlyfe3/venv/lib/python3.9/site-packages/flask_login/utils.py", line 290, in decorated_view
    return current_app.ensure_sync(func)(*args, **kwargs)
  File "/Users/danielweir/highlyfe3/app/main/routes.py", line 87, in About_Us
    no.text_input = text_input  #
AttributeError: 'list' object has no attribute 'text_input'
2023-08-10 01:29:31,910 INFO: Highlyfe startup [in /Users/danielweir/highlyfe3/app/__init__.py:59]
2023-08-10 01:30:54,276 INFO: Highlyfe startup [in /Users/danielweir/highlyfe3/app/__init__.py:59]
2023-08-10 01:31:31,950 INFO: Highlyfe startup [in /Users/danielweir/highlyfe3/app/__init__.py:59]
2023-08-10 01:31:42,200 ERROR: Exception on /About_Us [GET] [in /Users/danielweir/highlyfe3/venv/lib/python3.9/site-packages/flask/app.py:1414]
Traceback (most recent call last):
  File "/Users/danielweir/highlyfe3/venv/lib/python3.9/site-packages/flask/app.py", line 2190, in wsgi_app
    response = self.full_dispatch_request()
  File "/Users/danielweir/highlyfe3/venv/lib/python3.9/site-packages/flask/app.py", line 1486, in full_dispatch_request
    rv = self.handle_user_exception(e)
  File "/Users/danielweir/highlyfe3/venv/lib/python3.9/site-packages/flask/app.py", line 1484, in full_dispatch_request
    rv = self.dispatch_request()
  File "/Users/danielweir/highlyfe3/venv/lib/python3.9/site-packages/flask/app.py", line 1469, in dispatch_request
    return self.ensure_sync(self.view_functions[rule.endpoint])(**view_args)
  File "/Users/danielweir/highlyfe3/venv/lib/python3.9/site-packages/flask_login/utils.py", line 290, in decorated_view
    return current_app.ensure_sync(func)(*args, **kwargs)
  File "/Users/danielweir/highlyfe3/app/main/routes.py", line 130, in About_Us
    print(text_input)
UnboundLocalError: local variable 'text_input' referenced before assignment
2023-08-10 01:32:27,228 INFO: Highlyfe startup [in /Users/danielweir/highlyfe3/app/__init__.py:59]
