2023-08-11 19:07:00,561 ERROR: Exception on /edit_profile/clem [POST] [in /Users/danielweir/highlyfe3/venv/lib/python3.9/site-packages/flask/app.py:1414]
Traceback (most recent call last):
  File "/Users/danielweir/highlyfe3/venv/lib/python3.9/site-packages/sqlalchemy/engine/base.py", line 1965, in _exec_single_context
    self.dialect.do_execute(
  File "/Users/danielweir/highlyfe3/venv/lib/python3.9/site-packages/sqlalchemy/engine/default.py", line 921, in do_execute
    cursor.execute(statement, parameters)
sqlite3.IntegrityError: UNIQUE constraint failed: user.username

The above exception was the direct cause of the following exception:

Traceback (most recent call last):
  File "/Users/danielweir/highlyfe3/venv/lib/python3.9/site-packages/flask/app.py", line 2190, in wsgi_app
    response = self.full_dispatch_request()
  File "/Users/danielweir/highlyfe3/venv/lib/python3.9/site-packages/flask/app.py", line 1486, in full_dispatch_request
    rv = self.handle_user_exception(e)
  File "/Users/danielweir/highlyfe3/venv/lib/python3.9/site-packages/flask/app.py", line 1484, in full_dispatch_request
    rv = self.dispatch_request()
  File "/Users/danielweir/highlyfe3/venv/lib/python3.9/site-packages/flask/app.py", line 1469, in dispatch_request
    return self.ensure_sync(self.view_functions[rule.endpoint])(**view_args)
  File "/Users/danielweir/highlyfe3/venv/lib/python3.9/site-packages/flask_login/utils.py", line 290, in decorated_view
    return current_app.ensure_sync(func)(*args, **kwargs)
  File "/Users/danielweir/highlyfe3/app/main/routes.py", line 198, in edit_profile
    db.session.commit()
  File "/Users/danielweir/highlyfe3/venv/lib/python3.9/site-packages/sqlalchemy/orm/scoping.py", line 552, in commit
    return self._proxied.commit()
  File "/Users/danielweir/highlyfe3/venv/lib/python3.9/site-packages/sqlalchemy/orm/session.py", line 1920, in commit
    trans.commit(_to_root=True)
  File "<string>", line 2, in commit
  File "/Users/danielweir/highlyfe3/venv/lib/python3.9/site-packages/sqlalchemy/orm/state_changes.py", line 139, in _go
    ret_value = fn(self, *arg, **kw)
  File "/Users/danielweir/highlyfe3/venv/lib/python3.9/site-packages/sqlalchemy/orm/session.py", line 1236, in commit
    self._prepare_impl()
  File "<string>", line 2, in _prepare_impl
  File "/Users/danielweir/highlyfe3/venv/lib/python3.9/site-packages/sqlalchemy/orm/state_changes.py", line 139, in _go
    ret_value = fn(self, *arg, **kw)
  File "/Users/danielweir/highlyfe3/venv/lib/python3.9/site-packages/sqlalchemy/orm/session.py", line 1211, in _prepare_impl
    self.session.flush()
  File "/Users/danielweir/highlyfe3/venv/lib/python3.9/site-packages/sqlalchemy/orm/session.py", line 4163, in flush
    self._flush(objects)
  File "/Users/danielweir/highlyfe3/venv/lib/python3.9/site-packages/sqlalchemy/orm/session.py", line 4299, in _flush
    transaction.rollback(_capture_exception=True)
  File "/Users/danielweir/highlyfe3/venv/lib/python3.9/site-packages/sqlalchemy/util/langhelpers.py", line 147, in __exit__
    raise exc_value.with_traceback(exc_tb)
  File "/Users/danielweir/highlyfe3/venv/lib/python3.9/site-packages/sqlalchemy/orm/session.py", line 4259, in _flush
    flush_context.execute()
  File "/Users/danielweir/highlyfe3/venv/lib/python3.9/site-packages/sqlalchemy/orm/unitofwork.py", line 466, in execute
    rec.execute(self)
  File "/Users/danielweir/highlyfe3/venv/lib/python3.9/site-packages/sqlalchemy/orm/unitofwork.py", line 642, in execute
    util.preloaded.orm_persistence.save_obj(
  File "/Users/danielweir/highlyfe3/venv/lib/python3.9/site-packages/sqlalchemy/orm/persistence.py", line 85, in save_obj
    _emit_update_statements(
  File "/Users/danielweir/highlyfe3/venv/lib/python3.9/site-packages/sqlalchemy/orm/persistence.py", line 909, in _emit_update_statements
    c = connection.execute(
  File "/Users/danielweir/highlyfe3/venv/lib/python3.9/site-packages/sqlalchemy/engine/base.py", line 1412, in execute
    return meth(
  File "/Users/danielweir/highlyfe3/venv/lib/python3.9/site-packages/sqlalchemy/sql/elements.py", line 483, in _execute_on_connection
    return connection._execute_clauseelement(
  File "/Users/danielweir/highlyfe3/venv/lib/python3.9/site-packages/sqlalchemy/engine/base.py", line 1635, in _execute_clauseelement
    ret = self._execute_context(
  File "/Users/danielweir/highlyfe3/venv/lib/python3.9/site-packages/sqlalchemy/engine/base.py", line 1844, in _execute_context
    return self._exec_single_context(
  File "/Users/danielweir/highlyfe3/venv/lib/python3.9/site-packages/sqlalchemy/engine/base.py", line 1984, in _exec_single_context
    self._handle_dbapi_exception(
  File "/Users/danielweir/highlyfe3/venv/lib/python3.9/site-packages/sqlalchemy/engine/base.py", line 2339, in _handle_dbapi_exception
    raise sqlalchemy_exception.with_traceback(exc_info[2]) from e
  File "/Users/danielweir/highlyfe3/venv/lib/python3.9/site-packages/sqlalchemy/engine/base.py", line 1965, in _exec_single_context
    self.dialect.do_execute(
  File "/Users/danielweir/highlyfe3/venv/lib/python3.9/site-packages/sqlalchemy/engine/default.py", line 921, in do_execute
    cursor.execute(statement, parameters)
sqlalchemy.exc.IntegrityError: (sqlite3.IntegrityError) UNIQUE constraint failed: user.username
[SQL: UPDATE user SET username=? WHERE user.id = ?]
[parameters: ('Clem', 3)]
(Background on this error at: https://sqlalche.me/e/20/gkpj)
2023-08-11 19:08:56,505 INFO: Highlyfe startup [in /Users/danielweir/highlyfe3/app/__init__.py:59]
2023-08-11 19:09:12,486 ERROR: Exception on /edit_profile/clem [POST] [in /Users/danielweir/highlyfe3/venv/lib/python3.9/site-packages/flask/app.py:1414]
Traceback (most recent call last):
  File "/Users/danielweir/highlyfe3/venv/lib/python3.9/site-packages/flask/app.py", line 2190, in wsgi_app
    response = self.full_dispatch_request()
  File "/Users/danielweir/highlyfe3/venv/lib/python3.9/site-packages/flask/app.py", line 1486, in full_dispatch_request
    rv = self.handle_user_exception(e)
  File "/Users/danielweir/highlyfe3/venv/lib/python3.9/site-packages/flask/app.py", line 1484, in full_dispatch_request
    rv = self.dispatch_request()
  File "/Users/danielweir/highlyfe3/venv/lib/python3.9/site-packages/flask/app.py", line 1469, in dispatch_request
    return self.ensure_sync(self.view_functions[rule.endpoint])(**view_args)
  File "/Users/danielweir/highlyfe3/venv/lib/python3.9/site-packages/flask_login/utils.py", line 290, in decorated_view
    return current_app.ensure_sync(func)(*args, **kwargs)
  File "/Users/danielweir/highlyfe3/app/main/routes.py", line 195, in edit_profile
    if form.validate_on_submit():
  File "/Users/danielweir/highlyfe3/venv/lib/python3.9/site-packages/flask_wtf/form.py", line 86, in validate_on_submit
    return self.is_submitted() and self.validate(extra_validators=extra_validators)
TypeError: validate() got an unexpected keyword argument 'extra_validators'
2023-08-11 19:11:09,597 INFO: Highlyfe startup [in /Users/danielweir/highlyfe3/app/__init__.py:59]
2023-08-11 19:13:01,075 INFO: Highlyfe startup [in /Users/danielweir/highlyfe3/app/__init__.py:59]
2023-08-11 19:13:07,025 ERROR: Exception on /edit_profile/clem [POST] [in /Users/danielweir/highlyfe3/venv/lib/python3.9/site-packages/flask/app.py:1414]
Traceback (most recent call last):
  File "/Users/danielweir/highlyfe3/venv/lib/python3.9/site-packages/flask/app.py", line 2190, in wsgi_app
    response = self.full_dispatch_request()
  File "/Users/danielweir/highlyfe3/venv/lib/python3.9/site-packages/flask/app.py", line 1486, in full_dispatch_request
    rv = self.handle_user_exception(e)
  File "/Users/danielweir/highlyfe3/venv/lib/python3.9/site-packages/flask/app.py", line 1484, in full_dispatch_request
    rv = self.dispatch_request()
  File "/Users/danielweir/highlyfe3/venv/lib/python3.9/site-packages/flask/app.py", line 1469, in dispatch_request
    return self.ensure_sync(self.view_functions[rule.endpoint])(**view_args)
  File "/Users/danielweir/highlyfe3/venv/lib/python3.9/site-packages/flask_login/utils.py", line 290, in decorated_view
    return current_app.ensure_sync(func)(*args, **kwargs)
  File "/Users/danielweir/highlyfe3/app/main/routes.py", line 199, in edit_profile
    return redirect(url_for('main.edit_profile'))
  File "/Users/danielweir/highlyfe3/venv/lib/python3.9/site-packages/flask/helpers.py", line 225, in url_for
    return current_app.url_for(
  File "/Users/danielweir/highlyfe3/venv/lib/python3.9/site-packages/flask/app.py", line 1697, in url_for
    return self.handle_url_build_error(error, endpoint, values)
  File "/Users/danielweir/highlyfe3/venv/lib/python3.9/site-packages/flask/app.py", line 1686, in url_for
    rv = url_adapter.build(  # type: ignore[union-attr]
  File "/Users/danielweir/highlyfe3/venv/lib/python3.9/site-packages/werkzeug/routing/map.py", line 950, in build
    raise BuildError(endpoint, values, method, self)
werkzeug.routing.exceptions.BuildError: Could not build url for endpoint 'main.edit_profile'. Did you forget to specify values ['username']?
