2023-08-11 18:27:30,938 ERROR: Exception on /edit_profile/clem [POST] [in /Users/danielweir/highlyfe3/venv/lib/python3.9/site-packages/flask/app.py:1414]
Traceback (most recent call last):
  File "/Users/danielweir/highlyfe3/venv/lib/python3.9/site-packages/flask/app.py", line 2190, in wsgi_app
    response = self.full_dispatch_request()
  File "/Users/danielweir/highlyfe3/venv/lib/python3.9/site-packages/flask/app.py", line 1486, in full_dispatch_request
    rv = self.handle_user_exception(e)
  File "/Users/danielweir/highlyfe3/venv/lib/python3.9/site-packages/flask/app.py", line 1484, in full_dispatch_request
    rv = self.dispatch_request()
  File "/Users/danielweir/highlyfe3/venv/lib/python3.9/site-packages/flask/app.py", line 1469, in dispatch_request
    return self.ensure_sync(self.view_functions[rule.endpoint])(**view_args)
  File "/Users/danielweir/highlyfe3/venv/lib/python3.9/site-packages/flask_login/utils.py", line 290, in decorated_view
    return current_app.ensure_sync(func)(*args, **kwargs)
  File "/Users/danielweir/highlyfe3/app/main/routes.py", line 202, in edit_profile
    return redirect(url_for('edit_profile'))
  File "/Users/danielweir/highlyfe3/venv/lib/python3.9/site-packages/flask/helpers.py", line 225, in url_for
    return current_app.url_for(
  File "/Users/danielweir/highlyfe3/venv/lib/python3.9/site-packages/flask/app.py", line 1697, in url_for
    return self.handle_url_build_error(error, endpoint, values)
  File "/Users/danielweir/highlyfe3/venv/lib/python3.9/site-packages/flask/app.py", line 1686, in url_for
    rv = url_adapter.build(  # type: ignore[union-attr]
  File "/Users/danielweir/highlyfe3/venv/lib/python3.9/site-packages/werkzeug/routing/map.py", line 950, in build
    raise BuildError(endpoint, values, method, self)
werkzeug.routing.exceptions.BuildError: Could not build url for endpoint 'edit_profile'. Did you mean 'main.edit_profile' instead?
2023-08-11 18:27:43,108 ERROR: Exception on /edit_profile/clem [POST] [in /Users/danielweir/highlyfe3/venv/lib/python3.9/site-packages/flask/app.py:1414]
Traceback (most recent call last):
  File "/Users/danielweir/highlyfe3/venv/lib/python3.9/site-packages/flask/app.py", line 2190, in wsgi_app
    response = self.full_dispatch_request()
  File "/Users/danielweir/highlyfe3/venv/lib/python3.9/site-packages/flask/app.py", line 1486, in full_dispatch_request
    rv = self.handle_user_exception(e)
  File "/Users/danielweir/highlyfe3/venv/lib/python3.9/site-packages/flask/app.py", line 1484, in full_dispatch_request
    rv = self.dispatch_request()
  File "/Users/danielweir/highlyfe3/venv/lib/python3.9/site-packages/flask/app.py", line 1469, in dispatch_request
    return self.ensure_sync(self.view_functions[rule.endpoint])(**view_args)
  File "/Users/danielweir/highlyfe3/venv/lib/python3.9/site-packages/flask_login/utils.py", line 290, in decorated_view
    return current_app.ensure_sync(func)(*args, **kwargs)
  File "/Users/danielweir/highlyfe3/app/main/routes.py", line 202, in edit_profile
    return redirect(url_for('edit_profile'))
  File "/Users/danielweir/highlyfe3/venv/lib/python3.9/site-packages/flask/helpers.py", line 225, in url_for
    return current_app.url_for(
  File "/Users/danielweir/highlyfe3/venv/lib/python3.9/site-packages/flask/app.py", line 1697, in url_for
    return self.handle_url_build_error(error, endpoint, values)
  File "/Users/danielweir/highlyfe3/venv/lib/python3.9/site-packages/flask/app.py", line 1686, in url_for
    rv = url_adapter.build(  # type: ignore[union-attr]
  File "/Users/danielweir/highlyfe3/venv/lib/python3.9/site-packages/werkzeug/routing/map.py", line 950, in build
    raise BuildError(endpoint, values, method, self)
werkzeug.routing.exceptions.BuildError: Could not build url for endpoint 'edit_profile'. Did you mean 'main.edit_profile' instead?
2023-08-11 18:28:19,019 INFO: Highlyfe startup [in /Users/danielweir/highlyfe3/app/__init__.py:59]
2023-08-11 18:28:20,465 ERROR: Exception on /edit_profile/clem [POST] [in /Users/danielweir/highlyfe3/venv/lib/python3.9/site-packages/flask/app.py:1414]
Traceback (most recent call last):
  File "/Users/danielweir/highlyfe3/venv/lib/python3.9/site-packages/flask/app.py", line 2190, in wsgi_app
    response = self.full_dispatch_request()
  File "/Users/danielweir/highlyfe3/venv/lib/python3.9/site-packages/flask/app.py", line 1486, in full_dispatch_request
    rv = self.handle_user_exception(e)
  File "/Users/danielweir/highlyfe3/venv/lib/python3.9/site-packages/flask/app.py", line 1484, in full_dispatch_request
    rv = self.dispatch_request()
  File "/Users/danielweir/highlyfe3/venv/lib/python3.9/site-packages/flask/app.py", line 1469, in dispatch_request
    return self.ensure_sync(self.view_functions[rule.endpoint])(**view_args)
  File "/Users/danielweir/highlyfe3/venv/lib/python3.9/site-packages/flask_login/utils.py", line 290, in decorated_view
    return current_app.ensure_sync(func)(*args, **kwargs)
  File "/Users/danielweir/highlyfe3/app/main/routes.py", line 202, in edit_profile
    return redirect(url_for('main.edit_profile'))
  File "/Users/danielweir/highlyfe3/venv/lib/python3.9/site-packages/flask/helpers.py", line 225, in url_for
    return current_app.url_for(
  File "/Users/danielweir/highlyfe3/venv/lib/python3.9/site-packages/flask/app.py", line 1697, in url_for
    return self.handle_url_build_error(error, endpoint, values)
  File "/Users/danielweir/highlyfe3/venv/lib/python3.9/site-packages/flask/app.py", line 1686, in url_for
    rv = url_adapter.build(  # type: ignore[union-attr]
  File "/Users/danielweir/highlyfe3/venv/lib/python3.9/site-packages/werkzeug/routing/map.py", line 950, in build
    raise BuildError(endpoint, values, method, self)
werkzeug.routing.exceptions.BuildError: Could not build url for endpoint 'main.edit_profile'. Did you forget to specify values ['username']?
2023-08-11 18:28:48,427 INFO: Highlyfe startup [in /Users/danielweir/highlyfe3/app/__init__.py:59]
2023-08-11 18:31:45,702 INFO: Highlyfe startup [in /Users/danielweir/highlyfe3/app/__init__.py:59]
2023-08-11 18:32:03,019 INFO: Highlyfe startup [in /Users/danielweir/highlyfe3/app/__init__.py:59]
2023-08-11 18:32:19,909 INFO: Highlyfe startup [in /Users/danielweir/highlyfe3/app/__init__.py:59]
2023-08-11 18:32:44,562 ERROR: Exception on /edit_profile/danny [POST] [in /Users/danielweir/highlyfe3/venv/lib/python3.9/site-packages/flask/app.py:1414]
Traceback (most recent call last):
  File "/Users/danielweir/highlyfe3/venv/lib/python3.9/site-packages/flask/app.py", line 2190, in wsgi_app
    response = self.full_dispatch_request()
  File "/Users/danielweir/highlyfe3/venv/lib/python3.9/site-packages/flask/app.py", line 1486, in full_dispatch_request
    rv = self.handle_user_exception(e)
  File "/Users/danielweir/highlyfe3/venv/lib/python3.9/site-packages/flask/app.py", line 1484, in full_dispatch_request
    rv = self.dispatch_request()
  File "/Users/danielweir/highlyfe3/venv/lib/python3.9/site-packages/flask/app.py", line 1469, in dispatch_request
    return self.ensure_sync(self.view_functions[rule.endpoint])(**view_args)
  File "/Users/danielweir/highlyfe3/venv/lib/python3.9/site-packages/flask_login/utils.py", line 290, in decorated_view
    return current_app.ensure_sync(func)(*args, **kwargs)
  File "/Users/danielweir/highlyfe3/app/main/routes.py", line 195, in edit_profile
    if form.validate_on_submit():
  File "/Users/danielweir/highlyfe3/venv/lib/python3.9/site-packages/flask_wtf/form.py", line 86, in validate_on_submit
    return self.is_submitted() and self.validate(extra_validators=extra_validators)
  File "/Users/danielweir/highlyfe3/venv/lib/python3.9/site-packages/wtforms/form.py", line 329, in validate
    return super().validate(extra)
  File "/Users/danielweir/highlyfe3/venv/lib/python3.9/site-packages/wtforms/form.py", line 146, in validate
    if not field.validate(self, extra):
  File "/Users/danielweir/highlyfe3/venv/lib/python3.9/site-packages/wtforms/fields/core.py", line 242, in validate
    stop_validation = self._run_validation_chain(form, chain)
  File "/Users/danielweir/highlyfe3/venv/lib/python3.9/site-packages/wtforms/fields/core.py", line 262, in _run_validation_chain
    validator(form, self)
  File "/Users/danielweir/highlyfe3/app/main/forms.py", line 23, in validate_username
    user = User.query.filter_by(func.lower(username=self.username.data)).first()
  File "/Users/danielweir/highlyfe3/venv/lib/python3.9/site-packages/sqlalchemy/sql/functions.py", line 909, in __call__
    return Function(
TypeError: __init__() got an unexpected keyword argument 'username'
2023-08-11 18:33:47,803 INFO: Highlyfe startup [in /Users/danielweir/highlyfe3/app/__init__.py:59]
