2023-08-11 01:52:02,270 ERROR: Exception on /About_Us [GET] [in /Users/danielweir/highlyfe3/venv/lib/python3.9/site-packages/flask/app.py:1414]
Traceback (most recent call last):
  File "/Users/danielweir/highlyfe3/venv/lib/python3.9/site-packages/flask/app.py", line 2190, in wsgi_app
    response = self.full_dispatch_request()
  File "/Users/danielweir/highlyfe3/venv/lib/python3.9/site-packages/flask/app.py", line 1486, in full_dispatch_request
    rv = self.handle_user_exception(e)
  File "/Users/danielweir/highlyfe3/venv/lib/python3.9/site-packages/flask/app.py", line 1484, in full_dispatch_request
    rv = self.dispatch_request()
  File "/Users/danielweir/highlyfe3/venv/lib/python3.9/site-packages/flask/app.py", line 1469, in dispatch_request
    return self.ensure_sync(self.view_functions[rule.endpoint])(**view_args)
  File "/Users/danielweir/highlyfe3/venv/lib/python3.9/site-packages/flask_login/utils.py", line 290, in decorated_view
    return current_app.ensure_sync(func)(*args, **kwargs)
  File "/Users/danielweir/highlyfe3/app/main/routes.py", line 132, in About_Us
    if not text_input:
UnboundLocalError: local variable 'text_input' referenced before assignment
2023-08-11 01:52:47,983 INFO: Highlyfe startup [in /Users/danielweir/highlyfe3/app/__init__.py:59]
2023-08-11 01:52:50,298 ERROR: Exception on /About_Us [POST] [in /Users/danielweir/highlyfe3/venv/lib/python3.9/site-packages/flask/app.py:1414]
Traceback (most recent call last):
  File "/Users/danielweir/highlyfe3/venv/lib/python3.9/site-packages/flask/app.py", line 2190, in wsgi_app
    response = self.full_dispatch_request()
  File "/Users/danielweir/highlyfe3/venv/lib/python3.9/site-packages/flask/app.py", line 1486, in full_dispatch_request
    rv = self.handle_user_exception(e)
  File "/Users/danielweir/highlyfe3/venv/lib/python3.9/site-packages/flask/app.py", line 1484, in full_dispatch_request
    rv = self.dispatch_request()
  File "/Users/danielweir/highlyfe3/venv/lib/python3.9/site-packages/flask/app.py", line 1469, in dispatch_request
    return self.ensure_sync(self.view_functions[rule.endpoint])(**view_args)
  File "/Users/danielweir/highlyfe3/venv/lib/python3.9/site-packages/flask_login/utils.py", line 290, in decorated_view
    return current_app.ensure_sync(func)(*args, **kwargs)
  File "/Users/danielweir/highlyfe3/app/main/routes.py", line 98, in About_Us
    form.validate_on_sumbit==False
AttributeError: 'EmptyForm' object has no attribute 'validate_on_sumbit'
2023-08-11 01:53:16,238 INFO: Highlyfe startup [in /Users/danielweir/highlyfe3/app/__init__.py:59]
2023-08-11 02:42:26,690 INFO: Highlyfe startup [in /Users/danielweir/highlyfe3/app/__init__.py:59]
2023-08-11 02:44:31,608 INFO: Highlyfe startup [in /Users/danielweir/highlyfe3/app/__init__.py:59]
2023-08-11 02:46:16,013 INFO: Highlyfe startup [in /Users/danielweir/highlyfe3/app/__init__.py:59]
2023-08-11 02:46:30,590 INFO: Highlyfe startup [in /Users/danielweir/highlyfe3/app/__init__.py:59]
2023-08-11 02:47:23,194 INFO: Highlyfe startup [in /Users/danielweir/highlyfe3/app/__init__.py:59]
