2023-08-03 13:57:06,739 ERROR: Exception on /auth/reset_password_request [POST] [in /Users/danielweir/highlyfe3/venv/lib/python3.9/site-packages/flask/app.py:1414]
Traceback (most recent call last):
  File "/Users/danielweir/highlyfe3/venv/lib/python3.9/site-packages/flask/app.py", line 2190, in wsgi_app
    response = self.full_dispatch_request()
  File "/Users/danielweir/highlyfe3/venv/lib/python3.9/site-packages/flask/app.py", line 1486, in full_dispatch_request
    rv = self.handle_user_exception(e)
  File "/Users/danielweir/highlyfe3/venv/lib/python3.9/site-packages/flask/app.py", line 1484, in full_dispatch_request
    rv = self.dispatch_request()
  File "/Users/danielweir/highlyfe3/venv/lib/python3.9/site-packages/flask/app.py", line 1469, in dispatch_request
    return self.ensure_sync(self.view_functions[rule.endpoint])(**view_args)
  File "/Users/danielweir/highlyfe3/app/auth/routes.py", line 59, in reset_password_request
    send_mail(user)
  File "/Users/danielweir/highlyfe3/app/auth/email.py", line 19, in send_mail
    from_address = current_app.config['MAIL_DOMAIN']
KeyError: 'MAIL_DOMAIN'
2023-08-03 13:57:21,499 INFO: Highlyfe startup [in /Users/danielweir/highlyfe3/app/__init__.py:71]
2023-08-03 14:00:28,957 INFO: Highlyfe startup [in /Users/danielweir/highlyfe3/app/__init__.py:71]
2023-08-03 14:07:02,548 INFO: Highlyfe startup [in /Users/danielweir/highlyfe3/app/__init__.py:71]
2023-08-03 14:07:16,652 ERROR: Exception on /auth/reset_password_request [POST] [in /Users/danielweir/highlyfe3/venv/lib/python3.9/site-packages/flask/app.py:1414]
Traceback (most recent call last):
  File "/Users/danielweir/highlyfe3/venv/lib/python3.9/site-packages/flask/app.py", line 2190, in wsgi_app
    response = self.full_dispatch_request()
  File "/Users/danielweir/highlyfe3/venv/lib/python3.9/site-packages/flask/app.py", line 1486, in full_dispatch_request
    rv = self.handle_user_exception(e)
  File "/Users/danielweir/highlyfe3/venv/lib/python3.9/site-packages/flask/app.py", line 1484, in full_dispatch_request
    rv = self.dispatch_request()
  File "/Users/danielweir/highlyfe3/venv/lib/python3.9/site-packages/flask/app.py", line 1469, in dispatch_request
    return self.ensure_sync(self.view_functions[rule.endpoint])(**view_args)
  File "/Users/danielweir/highlyfe3/app/auth/routes.py", line 59, in reset_password_request
    send_mail(user)
  File "/Users/danielweir/highlyfe3/app/auth/email.py", line 26, in send_mail
    send_password_reset_email(to_address, from_address, subject, plaintext, html)
  File "/Users/danielweir/highlyfe3/app/auth/email.py", line 4, in send_password_reset_email
    to_address=dannybw212@gmail.com
NameError: name 'dannybw212' is not defined
2023-08-03 14:07:58,345 INFO: Highlyfe startup [in /Users/danielweir/highlyfe3/app/__init__.py:71]
2023-08-03 14:14:53,744 INFO: Highlyfe startup [in /Users/danielweir/highlyfe3/app/__init__.py:71]
2023-08-03 14:18:49,278 INFO: Highlyfe startup [in /Users/danielweir/highlyfe3/app/__init__.py:71]
2023-08-03 14:24:57,174 INFO: Highlyfe startup [in /Users/danielweir/highlyfe3/app/__init__.py:71]
2023-08-03 14:25:13,168 INFO: Highlyfe startup [in /Users/danielweir/highlyfe3/app/__init__.py:71]
2023-08-03 14:28:35,293 INFO: Highlyfe startup [in /Users/danielweir/highlyfe3/app/__init__.py:71]
2023-08-03 14:29:13,990 ERROR: Exception on /auth/reset_password_request [POST] [in /Users/danielweir/highlyfe3/venv/lib/python3.9/site-packages/flask/app.py:1414]
Traceback (most recent call last):
  File "/Users/danielweir/highlyfe3/venv/lib/python3.9/site-packages/flask/app.py", line 2190, in wsgi_app
    response = self.full_dispatch_request()
  File "/Users/danielweir/highlyfe3/venv/lib/python3.9/site-packages/flask/app.py", line 1486, in full_dispatch_request
    rv = self.handle_user_exception(e)
  File "/Users/danielweir/highlyfe3/venv/lib/python3.9/site-packages/flask/app.py", line 1484, in full_dispatch_request
    rv = self.dispatch_request()
  File "/Users/danielweir/highlyfe3/venv/lib/python3.9/site-packages/flask/app.py", line 1469, in dispatch_request
    return self.ensure_sync(self.view_functions[rule.endpoint])(**view_args)
  File "/Users/danielweir/highlyfe3/app/auth/routes.py", line 59, in reset_password_request
    send_mail(user)
TypeError: send_mail() missing 1 required positional argument: 'text'
2023-08-03 14:43:36,999 INFO: Highlyfe startup [in /Users/danielweir/highlyfe3/app/__init__.py:71]
2023-08-03 14:53:36,877 INFO: Highlyfe startup [in /Users/danielweir/highlyfe3/app/__init__.py:71]
2023-08-03 14:53:52,954 ERROR: Exception on /auth/reset_password_request [POST] [in /Users/danielweir/highlyfe3/venv/lib/python3.9/site-packages/flask/app.py:1414]
Traceback (most recent call last):
  File "/Users/danielweir/highlyfe3/venv/lib/python3.9/site-packages/flask/app.py", line 2190, in wsgi_app
    response = self.full_dispatch_request()
  File "/Users/danielweir/highlyfe3/venv/lib/python3.9/site-packages/flask/app.py", line 1486, in full_dispatch_request
    rv = self.handle_user_exception(e)
  File "/Users/danielweir/highlyfe3/venv/lib/python3.9/site-packages/flask/app.py", line 1484, in full_dispatch_request
    rv = self.dispatch_request()
  File "/Users/danielweir/highlyfe3/venv/lib/python3.9/site-packages/flask/app.py", line 1469, in dispatch_request
    return self.ensure_sync(self.view_functions[rule.endpoint])(**view_args)
  File "/Users/danielweir/highlyfe3/app/auth/routes.py", line 60, in reset_password_request
    html_content = render_template('templates/emails/reset_password_email.html',user=user,token=user.get_reset_password_token(),url_for=url_for)
  File "/Users/danielweir/highlyfe3/venv/lib/python3.9/site-packages/flask/templating.py", line 150, in render_template
    template = app.jinja_env.get_or_select_template(template_name_or_list)
  File "/Users/danielweir/highlyfe3/venv/lib/python3.9/site-packages/jinja2/environment.py", line 1081, in get_or_select_template
    return self.get_template(template_name_or_list, parent, globals)
  File "/Users/danielweir/highlyfe3/venv/lib/python3.9/site-packages/jinja2/environment.py", line 1010, in get_template
    return self._load_template(name, globals)
  File "/Users/danielweir/highlyfe3/venv/lib/python3.9/site-packages/jinja2/environment.py", line 969, in _load_template
    template = self.loader.load(self, name, self.make_globals(globals))
  File "/Users/danielweir/highlyfe3/venv/lib/python3.9/site-packages/jinja2/loaders.py", line 126, in load
    source, filename, uptodate = self.get_source(environment, name)
  File "/Users/danielweir/highlyfe3/venv/lib/python3.9/site-packages/flask/templating.py", line 64, in get_source
    return self._get_source_fast(environment, template)
  File "/Users/danielweir/highlyfe3/venv/lib/python3.9/site-packages/flask/templating.py", line 98, in _get_source_fast
    raise TemplateNotFound(template)
jinja2.exceptions.TemplateNotFound: templates/emails/reset_password_email.html
2023-08-03 14:54:10,386 INFO: Highlyfe startup [in /Users/danielweir/highlyfe3/app/__init__.py:71]
2023-08-03 14:54:12,565 ERROR: Exception on /auth/reset_password_request [POST] [in /Users/danielweir/highlyfe3/venv/lib/python3.9/site-packages/flask/app.py:1414]
Traceback (most recent call last):
  File "/Users/danielweir/highlyfe3/venv/lib/python3.9/site-packages/flask/app.py", line 2190, in wsgi_app
    response = self.full_dispatch_request()
  File "/Users/danielweir/highlyfe3/venv/lib/python3.9/site-packages/flask/app.py", line 1486, in full_dispatch_request
    rv = self.handle_user_exception(e)
  File "/Users/danielweir/highlyfe3/venv/lib/python3.9/site-packages/flask/app.py", line 1484, in full_dispatch_request
    rv = self.dispatch_request()
  File "/Users/danielweir/highlyfe3/venv/lib/python3.9/site-packages/flask/app.py", line 1469, in dispatch_request
    return self.ensure_sync(self.view_functions[rule.endpoint])(**view_args)
  File "/Users/danielweir/highlyfe3/app/auth/routes.py", line 60, in reset_password_request
    html_content = render_template('templates/email/reset_password_email.html',user=user,token=user.get_reset_password_token(),url_for=url_for)
  File "/Users/danielweir/highlyfe3/venv/lib/python3.9/site-packages/flask/templating.py", line 150, in render_template
    template = app.jinja_env.get_or_select_template(template_name_or_list)
  File "/Users/danielweir/highlyfe3/venv/lib/python3.9/site-packages/jinja2/environment.py", line 1081, in get_or_select_template
    return self.get_template(template_name_or_list, parent, globals)
  File "/Users/danielweir/highlyfe3/venv/lib/python3.9/site-packages/jinja2/environment.py", line 1010, in get_template
    return self._load_template(name, globals)
  File "/Users/danielweir/highlyfe3/venv/lib/python3.9/site-packages/jinja2/environment.py", line 969, in _load_template
    template = self.loader.load(self, name, self.make_globals(globals))
  File "/Users/danielweir/highlyfe3/venv/lib/python3.9/site-packages/jinja2/loaders.py", line 126, in load
    source, filename, uptodate = self.get_source(environment, name)
  File "/Users/danielweir/highlyfe3/venv/lib/python3.9/site-packages/flask/templating.py", line 64, in get_source
    return self._get_source_fast(environment, template)
  File "/Users/danielweir/highlyfe3/venv/lib/python3.9/site-packages/flask/templating.py", line 98, in _get_source_fast
    raise TemplateNotFound(template)
jinja2.exceptions.TemplateNotFound: templates/email/reset_password_email.html
2023-08-03 14:54:45,711 INFO: Highlyfe startup [in /Users/danielweir/highlyfe3/app/__init__.py:71]
